Workbook
Name IQ_CH: 110000
Name IQ_CQ: 5000
Name IQ_CY: 10000
Name IQ_DAILY: 500000
Name IQ_FH: 100000
Name IQ_FQ: 500
Name IQ_FY: 1000
Name IQ_LTM: 2000
Name IQ_MONTH: 15000
Name IQ_NTM: 6000
Name IQ_WEEK: 50000
Name IQ_YTD: 3000

Sheet VMI IV Calculator (20 years)
B2: ="Intrinsic Value Calculator ("&VLOOKUP(F12,AI32:AP34,7,FALSE)&" 20 years)" -> Intrinsic Value Calculator (Discounted Free Cash Flow Method 20 years)
B3: (Be consistent with the denominations used. Usually Millions $)
C6: KEY IN THE VALUES IN THE WHITE BOXES
C8: Name of Stock | F8: Microsoft | J8: Financial Statement Currency | M8: USD$
C10: Stock Symbol | F10: MSFT | J10: Stock Listing Currency | M10: USD$
C12: Valuation Method | F12: Discounted Free Cash Flow | J12: Exchange Rate | L12: ="1 "&M8&" is equivalent to " -> 1 USD$ is equivalent to | M12: 1 | N12: =M10 -> USD$
C14: =VLOOKUP(F12,AI32:AP34,2,FALSE) -> Free Cash Flow (Current) | F14: =$M$8 -> USD$ | G14: 101030.4 | J14: ="PV of 20 yr "&VLOOKUP(F12,AI32:AP34,3,FALSE) -> PV of 20 yr Free Cash Flow | M14: =$M$8 -> USD$ | N14: =SUM(F35:O35)+SUM(F40:O40) -> 3815917.2
C16: Total Debt (Short Term + LT Debt) | F16: =$M$8 -> USD$ | G16: 43208 | J16: Intrinsic Value before cash/debt | M16: =$M$8 -> USD$ | N16: =IF(F26<>0,N14/F26,0) -> 511.10597
C18: Cash and Short Term Investments | F18: =$M$8 -> USD$ | G18: 102012 | J18: less Debt per Share | M18: =$M$8 -> USD$ | N18: =IF(F26<>0,G16/F26,0) -> 5.7873024
C20: =VLOOKUP(F12,AI32:AP34,4,FALSE) -> Free Cash Flow Growth Rate (Yr 1 - 5) | F20: 0.1748 | J20: Plus (+) Cash Per Share | M20: =$M$8 -> USD$ | N20: =IF(F26<>0,G18/F26,0) -> 13.663541
C22: =VLOOKUP(F12,AI32:AP34,5,FALSE) -> Free Cash Flow growth rate (Yr 6 - 10) | F22: 0.15
C24: =VLOOKUP(F12,AI32:AP34,8,FALSE) -> Free Cash Flow Growth Rate (Yr 11 - 20) | F24: 0.04 | J24: Intrinsic Value Per Share (In Financial Statement Currency) | M24: =$M$8 -> USD$ | N24: =N16-N18+N20 -> 518.98221
C26: No. of Shares Outstanding | F26: 7466 | J26: Final Intrinsic Value Per Share (In Stock Listing Currency) | M26: =$M$10 -> USD$ | N26: =N24*M12 -> 518.98221
C28: Discount Rate | E28: 0.0661 | J28: (Discount)/Premium | M28: =N30/N26-1 -> -0.21816202
C30: Current Year | E30: 2025 | G30: NB: Take the last Fiscal Year as the Current Year | J30: Last Close | M30: =$M$10 -> USD$ | N30: 405.76
C32: Year | F32: =$E$30+1 -> 2026 | G32: =$E$30+2 -> 2027 | H32: =$E$30+3 -> 2028 | I32: =$E$30+4 -> 2029 | J32: =$E$30+5 -> 2030 | K32: =$E$30+6 -> 2031 | L32: =$E$30+7 -> 2032 | M32: =$E$30+8 -> 2033 | N32: =$E$30+9 -> 2034 | O32: =$E$30+10 -> 2035 | AI32: Discounted Cash Flow | AJ32: Operating Cash Flow (Current) | AK32: Operating Cash Flow | AL32: Cash Flow Growth Rate (Yr 1 - 5) | AM32: Cash Flow Growth Rate (Yr 6 - 10) | AN32: Operating Cash Flow (Projected) | AO32: Discounted Cash Flow Method | AP32: Cash Flow Growth Rate (Yr 11 - 20)
C33: =VLOOKUP(F12,AI32:AP34,6,FALSE) -> Free Cash Flow (Projected) | F33: =(G14)*(1+F20) -> 118690.51 | G33: =($F33)*(1+$F$20) -> 139437.62 | H33: =(G$33)*(1+$F$20) -> 163811.31 | I33: =(H$33)*(1+$F$20) -> 192445.53 | J33: =(I$33)*(1+$F$20) -> 226085.01 | K33: =(J$33)*(1+$F$22) -> 259997.76 | L33: =(K$33)*(1+$F$22) -> 298997.42 | M33: =(L$33)*(1+$F$22) -> 343847.03 | N33: =(M$33)*(1+$F$22) -> 395424.09 | O33: =(N$33)*(1+$F$22) -> 454737.7 | AI33: Discounted Net Income | AJ33: Net Income (Current) | AK33: Net Income | AL33: Net Income Growth Rate (Yr 1 - 5) | AM33: Net Income Growth Rate (Yr 6 - 10) | AN33: Net Income (Projected) | AO33: Discounted Net Income Method | AP33: Net Income Growth Rate (Yr 11 - 20)
C34: Discount Factor | F34: =1/(1+$E$28) -> 0.93799831 | G34: =F$34/(1+$E$28) -> 0.87984083 | H34: =G$34/(1+$E$28) -> 0.82528922 | I34: =H$34/(1+$E$28) -> 0.77411989 | J34: =I$34/(1+$E$28) -> 0.72612315 | K34: =J$34/(1+$E$28) -> 0.68110229 | L34: =K$34/(1+$E$28) -> 0.6388728 | M34: =L$34/(1+$E$28) -> 0.59926161 | N34: =M$34/(1+$E$28) -> 0.56210637 | O34: =N$34/(1+$E$28) -> 0.52725483 | AI34: Discounted Free Cash Flow | AJ34: Free Cash Flow (Current) | AK34: Free Cash Flow | AL34: Free Cash Flow Growth Rate (Yr 1 - 5) | AM34: Free Cash Flow growth rate (Yr 6 - 10) | AN34: Free Cash Flow (Projected) | AO34: Discounted Free Cash Flow Method | AP34: Free Cash Flow Growth Rate (Yr 11 - 20)
C35: Discounted Value | F35: =F33*F34 -> 111331.5 | G35: =G33*G34 -> 122682.91 | H35: =H33*H34 -> 135191.71 | I35: =I33*I34 -> 148975.91 | J35: =J33*J34 -> 164165.56 | K35: =K33*K34 -> 177085.07 | L35: =L33*L34 -> 191021.32 | M35: =M33*M34 -> 206054.33 | ... O35: =O33*O34 -> 239762.65
C37: Year | F37: =$E$30+11 -> 2036 | G37: =$E$30+12 -> 2037 | H37: =$E$30+13 -> 2038 | I37: =$E$30+14 -> 2039 | J37: =$E$30+15 -> 2040 | K37: =$E$30+16 -> 2041 | L37: =$E$30+17 -> 2042 | M37: =$E$30+18 -> 2043 | N37: =$E$30+19 -> 2044 | O37: =$E$30+20 -> 2045
C38: =VLOOKUP(F12,AI32:AP34,6,FALSE) -> Free Cash Flow (Projected) | F38: =(O$33)*(1+$F$24) -> 472927.21 | G38: =(F$38)*(1+$F$24) -> 491844.3 | H38: =(G$38)*(1+$F$24) -> 511518.07 | I38: =(H$38)*(1+$F$24) -> 531978.79 | J38: =(I$38)*(1+$F$24) -> 553257.95 | K38: =(J$38)*(1+$F$24) -> 575388.26 | L38: =(K$38)*(1+$F$24) -> 598403.79 | M38: =(L$38)*(1+$F$24) -> 622339.95 | N38: =(M$38)*(1+$F$24) -> 647233.54 | O38: =(N$38)*(1+$F$24) -> 673122.89
C39: Discount Factor | F39: =O$34/(1+$E$28) -> 0.49456414 | G39: =F$39/(1+$E$28) -> 0.46390033 | H39: =G$39/(1+$E$28) -> 0.43513772 | I39: =H$39/(1+$E$28) -> 0.40815845 | J39: =I$39/(1+$E$28) -> 0.38285194 | K39: =J$39/(1+$E$28) -> 0.35911447 | L39: =K$39/(1+$E$28) -> 0.33684877 | M39: =L$39/(1+$E$28) -> 0.31596358 | N39: =M$39/(1+$E$28) -> 0.2963733 | O39: =N$39/(1+$E$28) -> 0.27799766
C40: Discounted Value | F40: =F38*F39 -> 233892.84 | G40: =G38*G39 -> 228166.73 | H40: =H38*H39 -> 222580.81 | I40: =I38*I39 -> 217131.64 | J40: =J38*J39 -> 211815.88 | K40: =K38*K39 -> 206630.25 | L40: =L38*L39 -> 201571.58 | M40: =M38*M39 -> 196636.75 | ... O40: =O38*O39 -> 187126.58
C60: Discount Rate for US Stocks | J60: Discount Rate for China/HK Stocks
C62: BETA | E62: DISCOUNT RATE | J62: BETA | L62: DISCOUNT RATE
C63: Less than 0.80 | E63: =E74+0.8*E75 -> 0.057904 | J63: Less than 0.80 | L63: =L74+0.8*L75 -> 0.085576
C64: 0.9 | E64: =E74+C64*E75 -> 0.060632 | J64: 0.9 | L64: =L74+J64*L75 -> 0.092438
C65: 1 | E65: =E74+C65*E75 -> 0.06336 | J65: 1 | L65: =L74+J65*L75 -> 0.0993
C66: 1.1 | E66: =E74+C66*E75 -> 0.066088 | J66: 1.1 | L66: =L74+J66*L75 -> 0.106162
C67: 1.2 | E67: =E74+C67*E75 -> 0.068816 | J67: 1.2 | L67: =L74+J67*L75 -> 0.113024
C68: 1.3 | E68: =E74+C68*E75 -> 0.071544 | J68: 1.3 | L68: =L74+J68*L75 -> 0.119886
C69: 1.4 | E69: =E74+C69*E75 -> 0.074272 | J69: 1.4 | L69: =L74+J69*L75 -> 0.126748
C70: 1.5 | E70: =E74+C70*E75 -> 0.077 | J70: 1.5 | L70: =L74+J70*L75 -> 0.13361
C71: More than 1.6 | E71: =E74+1.6*E75 -> 0.079728 | J71: More than 1.6 | L71: =L74+1.6*L75 -> 0.140472
C73: Discount Rate = Risk Free Rate + Beta x Market Risk Premium | J73: Discount Rate = Risk Free Rate + Beta x Market Risk Premium
D74: Risk Free Rate = | E74: ='Discount Rate Data'!C17 -> 0.03608 | K74: Risk Free Rate = | L74: ='Discount Rate Data'!C31 -> 0.03068
D75: Average market risk premium = | E75: ='Discount Rate Data'!F17 -> 0.02728 | K75: Average market risk premium = | L75: ='Discount Rate Data'!F31 -> 0.06862
D76: Updated on | E76: ='Discount Rate Data'!C4 -> 46092 | K76: Updated on | L76: ='Discount Rate Data'!C4 -> 46092
C78: Source: | J78: Source:
C79: https://www.market-risk-premia.com/us.html | J79: http://www.market-risk-premia.com/hk.html
...

Sheet Discounted Earnings Per Share
A1: KEY IN THE VALUES IN RED
A2: Assuming a Discount rate of 4% per year.
A4: Intrinsic Value Calculator (Discounted Earnings Per Share Method 10 years)
D5: ( Be consisent with the denominations used. Usually $)
A7: EPS (current) | B7: =#REF! -> #REF!
A8: EPS growth rate | B8: =#REF! -> #REF!
A9: Discount Rate | B9: =#REF! -> #REF!
A10: Year | B10: =#REF!+1 -> #REF! | C10: =B10+1 -> #REF! | D10: =C10+1 -> #REF! | E10: =D10+1 -> #REF! | F10: =E10+1 -> #REF! | G10: =F10+1 -> #REF! | H10: =G10+1 -> #REF! | I10: =H10+1 -> #REF! | J10: =I10+1 -> #REF! | K10: =J10+1 -> #REF!
A11: EPS (Projected) | B11: =B7*(1+B8) -> #REF! | C11: =B11*(1+B8) -> #REF! | D11: =C11*(1+B8) -> #REF! | E11: =D11*(1+B8) -> #REF! | F11: =E11*(1+B8) -> #REF! | G11: =F11*(1+B8) -> #REF! | H11: =G11*(1+B8) -> #REF! | I11: =H11*(1+B8) -> #REF! | J11: =I11*(1+B8) -> #REF! | K11: =J11*(1+B8) -> #REF!
A12: Discount Factor | B12: =1/(1+$B$9) -> #REF! | C12: =B12/(1+$B$9) -> #REF! | D12: =C12/(1+$B$9) -> #REF! | E12: =D12/(1+$B$9) -> #REF! | F12: =E12/(1+$B$9) -> #REF! | G12: =F12/(1+$B$9) -> #REF! | H12: =G12/(1+$B$9) -> #REF! | I12: =H12/(1+$B$9) -> #REF! | J12: =I12/(1+$B$9) -> #REF! | K12: =J12/(1+$B$9) -> #REF!
A13: Discounted Value | B13: =B11*B12 -> #REF! | C13: =C11*C12 -> #REF! | D13: =D11*D12 -> #REF! | E13: =E11*E12 -> #REF! | F13: =F11*F12 -> #REF! | G13: =G11*G12 -> #REF! | H13: =H11*H12 -> #REF! | I13: =I11*I12 -> #REF! | ... K13: =K11*K12 -> #REF!
A15: Intrinsic Value: | B15: =SUM(B13:K13) -> #REF!
A17: Note: This assumes EPS growth rate remains constant throughout the 10 years
A18: In certain cases, you may want to lower or increase the growth rate after a few years.

Sheet Discounted Cash Flow
A1: KEY IN THE VALUES IN RED
A2: Assuming a Discount rate of 4% per year.
A4: Intrinsic Value Calculator (Discounted Cash Flow Method 10 years)
D5: (Be consistent with the denominations used. Usually Millions $)
A7: Operating Cash Flow (current) | C7: =#REF! -> #REF! | D7: million
A8: Cash flow growth rate | C8: =#REF! -> #REF!
A9: Discount Rate | C9: =#REF! -> #REF!
A12: Year | B12: =#REF!+1 -> #REF! | C12: =B12+1 -> #REF! | D12: =C12+1 -> #REF! | E12: =D12+1 -> #REF! | F12: =E12+1 -> #REF! | G12: =F12+1 -> #REF! | H12: =G12+1 -> #REF! | I12: =H12+1 -> #REF! | J12: =I12+1 -> #REF! | K12: =J12+1 -> #REF!
A13: Cash Flow (Projected) | B13: =C7*(1+C8) -> #REF! | C13: =B13*(1+$C$8) -> #REF! | D13: =C13*(1+$C$8) -> #REF! | E13: =D13*(1+$C$8) -> #REF! | F13: =E13*(1+$C$8) -> #REF! | G13: =F13*(1+$C$8) -> #REF! | H13: =G13*(1+$C$8) -> #REF! | I13: =H13*(1+$C$8) -> #REF! | J13: =I13*(1+$C$8) -> #REF! | K13: =J13*(1+$C$8) -> #REF!
A14: Discount Factor | B14: =1/(1+$C$9) -> #REF! | C14: =B14/(1+$C$9) -> #REF! | D14: =C14/(1+$C$9) -> #REF! | E14: =D14/(1+$C$9) -> #REF! | F14: =E14/(1+$C$9) -> #REF! | G14: =F14/(1+$C$9) -> #REF! | H14: =G14/(1+$C$9) -> #REF! | I14: =H14/(1+$C$9) -> #REF! | J14: =I14/(1+$C$9) -> #REF! | K14: =J14/(1+$C$9) -> #REF!
A15: Discounted Value | B15: =B13*B14 -> #REF! | C15: =C13*C14 -> #REF! | D15: =D13*D14 -> #REF! | E15: =E13*E14 -> #REF! | F15: =F13*F14 -> #REF! | G15: =G13*G14 -> #REF! | H15: =H13*H14 -> #REF! | I15: =I13*I14 -> #REF! | ... K15: =K13*K14 -> #REF!
A17: No. Shares Outstanding | C17: =#REF! -> #REF! | D17: million
A19: PV of 10 yr Cash flows | C19: =B15+C15+D15+E15+F15+G15+H15+I15+J15+K15 -> #REF! | D19: million
A20: Intrinsic Value per share | C20: =C19/C17 -> #REF!
A22: Note: This assumes Cash growth rate remains constant throughout the 10 years
A23: In certain cases, you may want to lower or increase the growth rate after a few years.

Sheet VMI IV Calculator (Mean PB)
B2: Intrinsic Value Calculator (Mean Price to Book Ratio / Mean PB Ratio)
C6: KEY IN THE VALUES IN THE WHITE BOXES
C8: Name of Stock | F8: JPMorgan Chase & Co | J8: Financial Statement Currency | M8: USD$
C10: Stock Symbol | F10: JPM | J10: Stock Listing Currency | M10: USD$
C12: Book Value (BV) per Share | F12: =$M$8 -> USD$ | G12: 100 | J12: Exchange Rate | L12: ="1 "&M8&" is equivalent to " -> 1 USD$ is equivalent to | M12: 1 | N12: =M10 -> USD$
C14: Number of Historical Data | F14: 5 years
E16: Date | F16: =DATE(YEAR(G16)-1,MONTH(G16),DAY(G16)) -> 42369 | G16: =DATE(YEAR(H16)-1,MONTH(H16),DAY(H16)) -> 42735 | H16: =DATE(YEAR(I16)-1,MONTH(I16),DAY(I16)) -> 43100 | I16: =DATE(YEAR(J16)-1,MONTH(J16),DAY(J16)) -> 43465 | J16: =DATE(YEAR(K16)-1,MONTH(K16),DAY(K16)) -> 43830 | K16: =DATE(YEAR(L16)-1,MONTH(L16),DAY(L16)) -> 44196 | L16: =DATE(YEAR(M16)-1,MONTH(M16),DAY(M16)) -> 44561 | M16: =DATE(YEAR(N16)-1,MONTH(N16),DAY(N16)) -> 44926 | N16: =DATE(YEAR(O16)-1,MONTH(O16),DAY(O16)) -> 45291 | O16: 45657
C17: Historical Price to Book Ratio | F17: 1.11 | G17: 1.35 | H17: 1.6 | I17: 1.4 | J17: 1.85 | K17: 1.61 | L17: 1.83 | M17: 1.54 | N17: 1.7 | O17: 2.08
C19: Mean Price to Book Ratio | F19: =IF(ISNUMBER(SEARCH("5",$F$14)),AVERAGE($K17:$O17),IF(ISNUMBER(SEARCH("10",$F$14)),AVERAGE($F17:$O17),"")) -> 1.752 | J19: 1 Standard Deviation (SD) Value | M19: =IF(ISNUMBER(SEARCH("5",$F$14)),_xlfn.STDEV.S($K17:$O17),IF(ISNUMBER(SEARCH("10",$F$14)),_xlfn.STDEV.S($F17:$O17),"")) -> 0.21300235
F21: Mean - 1 SD | H21: Mean - 2 SD | J21: Mean | L21: Mean + 1 SD | N21: Mean + 2 SD
C22: PB Ratio | F22: =$F$19-$M$19*2 -> 1.3259953 | H22: =$F$19-$M$19*1 -> 1.5389977 | J22: =F19 -> 1.752 | L22: =$F$19+$M$19*1 -> 1.9650023 | N22: =$F$19+$M$19*2 -> 2.1780047
C23: PB Ratio x BV per Share (In Financial Statement Currency) | E23: =$M$8 -> USD$ | F23: =F22*$G$12 -> 132.59953 | H23: =H22*$G$12 -> 153.89977 | J23: =J22*$G$12 -> 175.2 | L23: =L22*$G$12 -> 196.50023 | N23: =N22*$G$12 -> 217.80047
F25: IV - 2 SD | H25: IV - 1 SD | J25: Intrinsic Value (IV) | L25: IV + 1 SD | N25: IV + 2 SD
C26: PB Ratio x BV per Share (In Stock Listing Currency) | E26: =$M$10 -> USD$ | F26: =F22*$G$12*$M$12 -> 132.59953 | H26: =H22*$G$12*$M$12 -> 153.89977 | J26: =J22*$G$12*$M$12 -> 175.2 | L26: =L22*$G$12*$M$12 -> 196.50023 | N26: =N22*$G$12*$M$12 -> 217.80047
F28: Last Close | I28: =$M$10 -> USD$ | J28: 242.28
H30: (Discount)/Premium | J30: =$J$28/J26-1 -> 0.38287671
M36: ="© "&YEAR(TODAY())&" Piranha Ltd. All rights reserved." -> © 2026 Piranha Ltd. All rights reserved.

Sheet VMI IV Calculator (PSG)
B2: Intrinsic Value Calculator (Price to Sales Growth Ratio)
C6: KEY IN THE VALUES IN THE WHITE BOXES
C8: Name of Stock | F8: Palantir | J8: Financial Statement Currency | M8: USD$
C10: Stock Symbol | F10: PLTR | J10: Stock Listing Currency | M10: USD$
J12: Exchange Rate | L12: ="1 "&M8&" is equivalent to " -> 1 USD$ is equivalent to | M12: 1 | N12: =M10 -> USD$
C14: Sales Per Share | F14: =$M$8 -> USD$ | G14: 1.27 | J14: Current Price to Sales Growth (PSG) Ratio | M14: =N25/G14/(F16*100) -> 2.1574143
C16: Projected Growth Rate | F16: 0.3099 | J16: Fair PSG Ratio | M16: 0.2
J18: Intrinsic Value Per Share (In Financial Statement Currency) | M18: =$M$8 -> USD$ | N18: =M16*G14*F16*100 -> 7.87146
J20: Final Intrinsic Value Per Share (In Stock Listing Currency) | M20: =$M$10 -> USD$ | N20: =N18*M12 -> 7.87146
J22: (Discount)/Premium | M22: =N25/N20-1 -> 9.7870713
J25: Last Close | M25: =$M$10 -> USD$ | N25: 84.91
M31: ="© "&YEAR(TODAY())&" Piranha Ltd. All rights reserved." -> © 2026 Piranha Ltd. All rights reserved.

Sheet VMI Portfolio Dashboard
B2: PORTFOLIO DASHBOARD
B3: NOTE: EVERYTHING IN THIS PAGE IS CALCULATED AUTOMATICALLY
B5: Breakdown by Holdings (Market Value)
B45: Breakdown by Type (Market Value)
B46: TOTAL | G46: US | L46: China/HK | Q46: Singapore | V46: Australia
B47: Type | C47: Count | D47: Market Value (in USD) | E47: Percentage by Market Value | G47: Type | H47: Count | I47: Market Value (in USD) | J47: Percentage by Market Value | L47: Type | M47: Count | N47: Market Value (in USD) | O47: Percentage by Market Value | Q47: Type | R47: Count | S47: Market Value (in USD) | T47: Percentage by Market Value | V47: Type | W47: Count | X47: Market Value (in USD) | Y47: Percentage by Market Value
B48: Cyclical | C48: =COUNTIFS(_TrackerTable35[Type],_USDashboardTable561031[[#This Row],[Type]]) -> 1 | D48: =SUMIFS(_TrackerTable35[Market Value (in USD)],_TrackerTable35[Type],_USDashboardTable561031[[#This Row],[Type]]) -> 2948.1481 | E48: =IF(_USDashboardTable561031[[#Totals],[Market Value (in USD)]]>0,_USDashboardTable561031[[#This Row],[Market Value (in USD)]]/_USDashboardTable561031[[#Totals],[Market Value (in USD)]],0) -> 0.055498548 | G48: Cyclical | H48: =COUNTIFS(_TrackerTable35[Country],G$46,_TrackerTable35[Type],_USDashboardTable429[[#This Row],[Type]]) -> 0 | I48: =SUMIFS(_TrackerTable35[Market Value (in USD)],_TrackerTable35[Country],G$46,_TrackerTable35[Type],_USDashboardTable429[[#This Row],[Type]]) -> 0 | J48: =IF(_USDashboardTable429[[#Totals],[Market Value (in USD)]]>0,_USDashboardTable429[[#This Row],[Market Value (in USD)]]/_USDashboardTable429[[#Totals],[Market Value (in USD)]],0) -> 0 | L48: Cyclical | M48: =COUNTIFS(_TrackerTable35[Country],L$46,_TrackerTable35[Type],_USDashboardTable5930[[#This Row],[Type]]) -> 0 | N48: =SUMIFS(_TrackerTable35[Market Value (in USD)],_TrackerTable35[Country],L$46,_TrackerTable35[Type],_USDashboardTable5930[[#This Row],[Type]]) -> 0 | O48: =IF(_USDashboardTable5930[[#Totals],[Market Value (in USD)]]>0,_USDashboardTable5930[[#This Row],[Market Value (in USD)]]/_USDashboardTable5930[[#Totals],[Market Value (in USD)]],0) -> 0 | Q48: Cyclical | R48: =COUNTIFS(_TrackerTable35[Country],Q$46,_TrackerTable35[Type],_USDashboardTable571132[[#This Row],[Type]]) -> 1 | S48: =SUMIFS(_TrackerTable35[Market Value (in USD)],_TrackerTable35[Country],Q$46,_TrackerTable35[Type],_USDashboardTable571132[[#This Row],[Type]]) -> 2948.1481 | T48: =IF(_USDashboardTable571132[[#Totals],[Market Value (in USD)]]>0,_USDashboardTable571132[[#This Row],[Market Value (in USD)]]/_USDashboardTable571132[[#Totals],[Market Value (in USD)]],0) -> 1 | V48: Cyclical | W48: =COUNTIFS(_TrackerTable35[Country],V$46,_TrackerTable35[Type],_USDashboardTable57111534[[#This Row],[Type]]) -> 0 | X48: =SUMIFS(_TrackerTable35[Market Value (in USD)],_TrackerTable35[Country],V$46,_TrackerTable35[Type],_USDashboardTable57111534[[#This Row],[Type]]) -> 0 | Y48: =IF(_USDashboardTable57111534[[#Totals],[Market Value (in USD)]]>0,_USDashboardTable57111534[[#This Row],[Market Value (in USD)]]/_USDashboardTable57111534[[#Totals],[Market Value (in USD)]],0) -> 0
B49: Defensive | C49: =COUNTIFS(_TrackerTable35[Type],_USDashboardTable561031[[#This Row],[Type]]) -> 2 | D49: =SUMIFS(_TrackerTable35[Market Value (in USD)],_TrackerTable35[Type],_USDashboardTable561031[[#This Row],[Type]]) -> 12776.42 | E49: =IF(_USDashboardTable561031[[#Totals],[Market Value (in USD)]]>0,_USDashboardTable561031[[#This Row],[Market Value (in USD)]]/_USDashboardTable561031[[#Totals],[Market Value (in USD)]],0) -> 0.24051463 | G49: Defensive | H49: =COUNTIFS(_TrackerTable35[Country],G$46,_TrackerTable35[Type],_USDashboardTable429[[#This Row],[Type]]) -> 2 | I49: =SUMIFS(_TrackerTable35[Market Value (in USD)],_TrackerTable35[Country],G$46,_TrackerTable35[Type],_USDashboardTable429[[#This Row],[Type]]) -> 12776.42 | J49: =IF(_USDashboardTable429[[#Totals],[Market Value (in USD)]]>0,_USDashboardTable429[[#This Row],[Market Value (in USD)]]/_USDashboardTable429[[#Totals],[Market Value (in USD)]],0) -> 0.37499971 | L49: Defensive | M49: =COUNTIFS(_TrackerTable35[Country],L$46,_TrackerTable35[Type],_USDashboardTable5930[[#This Row],[Type]]) -> 0 | N49: =SUMIFS(_TrackerTable35[Market Value (in USD)],_TrackerTable35[Country],L$46,_TrackerTable35[Type],_USDashboardTable5930[[#This Row],[Type]]) -> 0 | O49: =IF(_USDashboardTable5930[[#Totals],[Market Value (in USD)]]>0,_USDashboardTable5930[[#This Row],[Market Value (in USD)]]/_USDashboardTable5930[[#Totals],[Market Value (in USD)]],0) -> 0 | Q49: Defensive | R49: =COUNTIFS(_TrackerTable35[Country],Q$46,_TrackerTable35[Type],_USDashboardTable571132[[#This Row],[Type]]) -> 0 | S49: =SUMIFS(_TrackerTable35[Market Value (in USD)],_TrackerTable35[Country],Q$46,_TrackerTable35[Type],_USDashboardTable571132[[#This Row],[Type]]) -> 0 | T49: =IF(_USDashboardTable571132[[#Totals],[Market Value (in USD)]]>0,_USDashboardTable571132[[#This Row],[Market Value (in USD)]]/_USDashboardTable571132[[#Totals],[Market Value (in USD)]],0) -> 0 | V49: Defensive | W49: =COUNTIFS(_TrackerTable35[Country],V$46,_TrackerTable35[Type],_USDashboardTable57111534[[#This Row],[Type]]) -> 0 | X49: =SUMIFS(_TrackerTable35[Market Value (in USD)],_TrackerTable35[Country],V$46,_TrackerTable35[Type],_USDashboardTable57111534[[#This Row],[Type]]) -> 0 | Y49: =IF(_USDashboardTable57111534[[#Totals],[Market Value (in USD)]]>0,_USDashboardTable57111534[[#This Row],[Market Value (in USD)]]/_USDashboardTable57111534[[#Totals],[Market Value (in USD)]],0) -> 0
B50: Moderate Cyclical | C50: =COUNTIFS(_TrackerTable35[Type],_USDashboardTable561031[[#This Row],[Type]]) -> 6 | D50: =SUMIFS(_TrackerTable35[Market Value (in USD)],_TrackerTable35[Type],_USDashboardTable561031[[#This Row],[Type]]) -> 37396.608 | E50: =IF(_USDashboardTable561031[[#Totals],[Market Value (in USD)]]>0,_USDashboardTable561031[[#This Row],[Market Value (in USD)]]/_USDashboardTable561031[[#Totals],[Market Value (in USD)]],0) -> 0.70398682 | G50: Moderate Cyclical | H50: =COUNTIFS(_TrackerTable35[Country],G$46,_TrackerTable35[Type],_USDashboardTable429[[#This Row],[Type]]) -> 3 | I50: =SUMIFS(_TrackerTable35[Market Value (in USD)],_TrackerTable35[Country],G$46,_TrackerTable35[Type],_USDashboardTable429[[#This Row],[Type]]) -> 21294.06 | J50: =IF(_USDashboardTable429[[#Totals],[Market Value (in USD)]]>0,_USDashboardTable429[[#This Row],[Market Value (in USD)]]/_USDashboardTable429[[#Totals],[Market Value (in USD)]],0) -> 0.62500029 | L50: Moderate Cyclical | M50: =COUNTIFS(_TrackerTable35[Country],L$46,_TrackerTable35[Type],_USDashboardTable5930[[#This Row],[Type]]) -> 3 | N50: =SUMIFS(_TrackerTable35[Market Value (in USD)],_TrackerTable35[Country],L$46,_TrackerTable35[Type],_USDashboardTable5930[[#This Row],[Type]]) -> 16102.548 | O50: =IF(_USDashboardTable5930[[#Totals],[Market Value (in USD)]]>0,_USDashboardTable5930[[#This Row],[Market Value (in USD)]]/_USDashboardTable5930[[#Totals],[Market Value (in USD)]],0) -> 1 | Q50: Moderate Cyclical | R50: =COUNTIFS(_TrackerTable35[Country],Q$46,_TrackerTable35[Type],_USDashboardTable571132[[#This Row],[Type]]) -> 0 | S50: =SUMIFS(_TrackerTable35[Market Value (in USD)],_TrackerTable35[Country],Q$46,_TrackerTable35[Type],_USDashboardTable571132[[#This Row],[Type]]) -> 0 | T50: =IF(_USDashboardTable571132[[#Totals],[Market Value (in USD)]]>0,_USDashboardTable571132[[#This Row],[Market Value (in USD)]]/_USDashboardTable571132[[#Totals],[Market Value (in USD)]],0) -> 0 | V50: Moderate Cyclical | W50: =COUNTIFS(_TrackerTable35[Country],V$46,_TrackerTable35[Type],_USDashboardTable57111534[[#This Row],[Type]]) -> 0 | X50: =SUMIFS(_TrackerTable35[Market Value (in USD)],_TrackerTable35[Country],V$46,_TrackerTable35[Type],_USDashboardTable57111534[[#This Row],[Type]]) -> 0 | Y50: =IF(_USDashboardTable57111534[[#Totals],[Market Value (in USD)]]>0,_USDashboardTable57111534[[#This Row],[Market Value (in USD)]]/_USDashboardTable57111534[[#Totals],[Market Value (in USD)]],0) -> 0
B51: TOTAL | C51: =SUBTOTAL(109,_USDashboardTable561031[Count]) -> 9 | D51: =SUBTOTAL(109,_USDashboardTable561031[Market Value (in USD)]) -> 53121.177 | E51: =SUBTOTAL(109,_USDashboardTable561031[Percentage by Market Value]) -> 1 | G51: TOTAL | H51: =SUBTOTAL(109,_USDashboardTable429[Count]) -> 5 | I51: =SUBTOTAL(109,_USDashboardTable429[Market Value (in USD)]) -> 34070.48 | J51: =SUBTOTAL(109,_USDashboardTable429[Percentage by Market Value]) -> 1 | L51: TOTAL | M51: =SUBTOTAL(109,_USDashboardTable5930[Count]) -> 3 | N51: =SUBTOTAL(109,_USDashboardTable5930[Market Value (in USD)]) -> 16102.548 | O51: =SUBTOTAL(109,_USDashboardTable5930[Percentage by Market Value]) -> 1 | Q51: TOTAL | R51: =SUBTOTAL(109,_USDashboardTable571132[Count]) -> 1 | S51: =SUBTOTAL(109,_USDashboardTable571132[Market Value (in USD)]) -> 2948.1481 | T51: =SUBTOTAL(109,_USDashboardTable571132[Percentage by Market Value]) -> 1 | V51: TOTAL | W51: =SUBTOTAL(109,_USDashboardTable57111534[Count]) -> 0 | X51: =SUBTOTAL(109,_USDashboardTable57111534[Market Value (in USD)]) -> 0 | Y51: =SUBTOTAL(109,_USDashboardTable57111534[Percentage by Market Value]) -> 0
B104: Breakdown by Category (Market Value)
B105: TOTAL | G105: US | L105: China/HK | Q105: Singapore | V105: Australia
B106: Category | C106: Count | D106: Market Value (in USD) | E106: Percentage by Market Value | G106: Category | H106: Count | I106: Market Value (in USD) | J106: Percentage by Market Value | L106: Category | M106: Count | N106: Market Value (in USD) | O106: Percentage by Market Value | Q106: Category | R106: Count | S106: Market Value (in USD) | T106: Percentage by Market Value | V106: Category | W106: Count | X106: Market Value (in USD) | Y106: Percentage by Market Value
B107: Cash Cow | C107: =COUNTIFS(_TrackerTable35[Category],_USDashboardTable5626[[#This Row],[Category]]) -> 1 | D107: =SUMIFS(_TrackerTable35[Market Value (in USD)],_TrackerTable35[Category],_USDashboardTable5626[[#This Row],[Category]]) -> 2948.1481 | E107: =IF(_USDashboardTable5626[[#Totals],[Market Value (in USD)]]>0,_USDashboardTable5626[[#This Row],[Market Value (in USD)]]/_USDashboardTable5626[[#Totals],[Market Value (in USD)]],0) -> 0.055498548 | G107: Cash Cow | H107: =COUNTIFS(_TrackerTable35[Country],G$105,_TrackerTable35[Category],_USDashboardTable24[[#This Row],[Category]]) -> 0 | I107: =SUMIFS(_TrackerTable35[Market Value (in USD)],_TrackerTable35[Country],G$105,_TrackerTable35[Category],_USDashboardTable24[[#This Row],[Category]]) -> 0 | J107: =IF(_USDashboardTable24[[#Totals],[Market Value (in USD)]]>0,_USDashboardTable24[[#This Row],[Market Value (in USD)]]/_USDashboardTable24[[#Totals],[Market Value (in USD)]],0) -> 0 | L107: Cash Cow | M107: =COUNTIFS(_TrackerTable35[Country],L$105,_TrackerTable35[Category],_USDashboardTable525[[#This Row],[Category]]) -> 0 | N107: =SUMIFS(_TrackerTable35[Market Value (in USD)],_TrackerTable35[Country],L$105,_TrackerTable35[Category],_USDashboardTable525[[#This Row],[Category]]) -> 0 | O107: =IF(_USDashboardTable525[[#Totals],[Market Value (in USD)]]>0,_USDashboardTable525[[#This Row],[Market Value (in USD)]]/_USDashboardTable525[[#Totals],[Market Value (in USD)]],0) -> 0 | Q107: Cash Cow | R107: =COUNTIFS(_TrackerTable35[Country],Q$105,_TrackerTable35[Category],_USDashboardTable5727[[#This Row],[Category]]) -> 1 | S107: =SUMIFS(_TrackerTable35[Market Value (in USD)],_TrackerTable35[Country],Q$105,_TrackerTable35[Category],_USDashboardTable5727[[#This Row],[Category]]) -> 2948.1481 | T107: =IF(_USDashboardTable5727[[#Totals],[Market Value (in USD)]]>0,_USDashboardTable5727[[#This Row],[Market Value (in USD)]]/_USDashboardTable5727[[#Totals],[Market Value (in USD)]],0) -> 1 | V107: Cash Cow | W107: =COUNTIFS(_TrackerTable35[Country],V$105,_TrackerTable35[Category],_USDashboardTable571433[[#This Row],[Category]]) -> 0 | X107: =SUMIFS(_TrackerTable35[Market Value (in USD)],_TrackerTable35[Country],V$105,_TrackerTable35[Category],_USDashboardTable571433[[#This Row],[Category]]) -> 0 | Y107: =IF(_USDashboardTable571433[[#Totals],[Market Value (in USD)]]>0,_USDashboardTable571433[[#This Row],[Market Value (in USD)]]/_USDashboardTable571433[[#Totals],[Market Value (in USD)]],0) -> 0
B108: Deep Cyclical | C108: =COUNTIFS(_TrackerTable35[Category],_USDashboardTable5626[[#This Row],[Category]]) -> 0 | D108: =SUMIFS(_TrackerTable35[Market Value (in USD)],_TrackerTable35[Category],_USDashboardTable5626[[#This Row],[Category]]) -> 0 | E108: =IF(_USDashboardTable5626[[#Totals],[Market Value (in USD)]]>0,_USDashboardTable5626[[#This Row],[Market Value (in USD)]]/_USDashboardTable5626[[#Totals],[Market Value (in USD)]],0) -> 0 | G108: Deep Cyclical | H108: =COUNTIFS(_TrackerTable35[Country],G$105,_TrackerTable35[Category],_USDashboardTable24[[#This Row],[Category]]) -> 0 | I108: =SUMIFS(_TrackerTable35[Market Value (in USD)],_TrackerTable35[Country],G$105,_TrackerTable35[Category],_USDashboardTable24[[#This Row],[Category]]) -> 0 | J108: =IF(_USDashboardTable24[[#Totals],[Market Value (in USD)]]>0,_USDashboardTable24[[#This Row],[Market Value (in USD)]]/_USDashboardTable24[[#Totals],[Market Value (in USD)]],0) -> 0 | L108: Deep Cyclical | M108: =COUNTIFS(_TrackerTable35[Country],L$105,_TrackerTable35[Category],_USDashboardTable525[[#This Row],[Category]]) -> 0 | N108: =SUMIFS(_TrackerTable35[Market Value (in USD)],_TrackerTable35[Country],L$105,_TrackerTable35[Category],_USDashboardTable525[[#This Row],[Category]]) -> 0 | O108: =IF(_USDashboardTable525[[#Totals],[Market Value (in USD)]]>0,_USDashboardTable525[[#This Row],[Market Value (in USD)]]/_USDashboardTable525[[#Totals],[Market Value (in USD)]],0) -> 0 | Q108: Deep Cyclical | R108: =COUNTIFS(_TrackerTable35[Country],Q$105,_TrackerTable35[Category],_USDashboardTable5727[[#This Row],[Category]]) -> 0 | S108: =SUMIFS(_TrackerTable35[Market Value (in USD)],_TrackerTable35[Country],Q$105,_TrackerTable35[Category],_USDashboardTable5727[[#This Row],[Category]]) -> 0 | T108: =IF(_USDashboardTable5727[[#Totals],[Market Value (in USD)]]>0,_USDashboardTable5727[[#This Row],[Market Value (in USD)]]/_USDashboardTable5727[[#Totals],[Market Value (in USD)]],0) -> 0 | V108: Deep Cyclical | W108: =COUNTIFS(_TrackerTable35[Country],V$105,_TrackerTable35[Category],_USDashboardTable571433[[#This Row],[Category]]) -> 0 | X108: =SUMIFS(_TrackerTable35[Market Value (in USD)],_TrackerTable35[Country],V$105,_TrackerTable35[Category],_USDashboardTable571433[[#This Row],[Category]]) -> 0 | Y108: =IF(_USDashboardTable571433[[#Totals],[Market Value (in USD)]]>0,_USDashboardTable571433[[#This Row],[Market Value (in USD)]]/_USDashboardTable571433[[#Totals],[Market Value (in USD)]],0) -> 0
B109: Deep Value | C109: =COUNTIFS(_TrackerTable35[Category],_USDashboardTable5626[[#This Row],[Category]]) -> 0 | D109: =SUMIFS(_TrackerTable35[Market Value (in USD)],_TrackerTable35[Category],_USDashboardTable5626[[#This Row],[Category]]) -> 0 | E109: =IF(_USDashboardTable5626[[#Totals],[Market Value (in USD)]]>0,_USDashboardTable5626[[#This Row],[Market Value (in USD)]]/_USDashboardTable5626[[#Totals],[Market Value (in USD)]],0) -> 0 | G109: Deep Value | H109: =COUNTIFS(_TrackerTable35[Country],G$105,_TrackerTable35[Category],_USDashboardTable24[[#This Row],[Category]]) -> 0 | I109: =SUMIFS(_TrackerTable35[Market Value (in USD)],_TrackerTable35[Country],G$105,_TrackerTable35[Category],_USDashboardTable24[[#This Row],[Category]]) -> 0 | J109: =IF(_USDashboardTable24[[#Totals],[Market Value (in USD)]]>0,_USDashboardTable24[[#This Row],[Market Value (in USD)]]/_USDashboardTable24[[#Totals],[Market Value (in USD)]],0) -> 0 | L109: Deep Value | M109: =COUNTIFS(_TrackerTable35[Country],L$105,_TrackerTable35[Category],_USDashboardTable525[[#This Row],[Category]]) -> 0 | N109: =SUMIFS(_TrackerTable35[Market Value (in USD)],_TrackerTable35[Country],L$105,_TrackerTable35[Category],_USDashboardTable525[[#This Row],[Category]]) -> 0 | O109: =IF(_USDashboardTable525[[#Totals],[Market Value (in USD)]]>0,_USDashboardTable525[[#This Row],[Market Value (in USD)]]/_USDashboardTable525[[#Totals],[Market Value (in USD)]],0) -> 0 | Q109: Deep Value | R109: =COUNTIFS(_TrackerTable35[Country],Q$105,_TrackerTable35[Category],_USDashboardTable5727[[#This Row],[Category]]) -> 0 | S109: =SUMIFS(_TrackerTable35[Market Value (in USD)],_TrackerTable35[Country],Q$105,_TrackerTable35[Category],_USDashboardTable5727[[#This Row],[Category]]) -> 0 | T109: =IF(_USDashboardTable5727[[#Totals],[Market Value (in USD)]]>0,_USDashboardTable5727[[#This Row],[Market Value (in USD)]]/_USDashboardTable5727[[#Totals],[Market Value (in USD)]],0) -> 0 | V109: Deep Value | W109: =COUNTIFS(_TrackerTable35[Country],V$105,_TrackerTable35[Category],_USDashboardTable571433[[#This Row],[Category]]) -> 0 | X109: =SUMIFS(_TrackerTable35[Market Value (in USD)],_TrackerTable35[Country],V$105,_TrackerTable35[Category],_USDashboardTable571433[[#This Row],[Category]]) -> 0 | Y109: =IF(_USDashboardTable571433[[#Totals],[Market Value (in USD)]]>0,_USDashboardTable571433[[#This Row],[Market Value (in USD)]]/_USDashboardTable571433[[#Totals],[Market Value (in USD)]],0) -> 0
B110: ETF | C110: =COUNTIFS(_TrackerTable35[Category],_USDashboardTable5626[[#This Row],[Category]]) -> 1 | D110: =SUMIFS(_TrackerTable35[Market Value (in USD)],_TrackerTable35[Category],_USDashboardTable5626[[#This Row],[Category]]) -> 5955.18 | E110: =IF(_USDashboardTable5626[[#Totals],[Market Value (in USD)]]>0,_USDashboardTable5626[[#This Row],[Market Value (in USD)]]/_USDashboardTable5626[[#Totals],[Market Value (in USD)]],0) -> 0.11210557 | G110: ETF | H110: =COUNTIFS(_TrackerTable35[Country],G$105,_TrackerTable35[Category],_USDashboardTable24[[#This Row],[Category]]) -> 0 | I110: =SUMIFS(_TrackerTable35[Market Value (in USD)],_TrackerTable35[Country],G$105,_TrackerTable35[Category],_USDashboardTable24[[#This Row],[Category]]) -> 0 | J110: =IF(_USDashboardTable24[[#Totals],[Market Value (in USD)]]>0,_USDashboardTable24[[#This Row],[Market Value (in USD)]]/_USDashboardTable24[[#Totals],[Market Value (in USD)]],0) -> 0 | L110: ETF | M110: =COUNTIFS(_TrackerTable35[Country],L$105,_TrackerTable35[Category],_USDashboardTable525[[#This Row],[Category]]) -> 1 | N110: =SUMIFS(_TrackerTable35[Market Value (in USD)],_TrackerTable35[Country],L$105,_TrackerTable35[Category],_USDashboardTable525[[#This Row],[Category]]) -> 5955.18 | O110: =IF(_USDashboardTable525[[#Totals],[Market Value (in USD)]]>0,_USDashboardTable525[[#This Row],[Market Value (in USD)]]/_USDashboardTable525[[#Totals],[Market Value (in USD)]],0) -> 0.36982842 | Q110: ETF | R110: =COUNTIFS(_TrackerTable35[Country],Q$105,_TrackerTable35[Category],_USDashboardTable5727[[#This Row],[Category]]) -> 0 | S110: =SUMIFS(_TrackerTable35[Market Value (in USD)],_TrackerTable35[Country],Q$105,_TrackerTable35[Category],_USDashboardTable5727[[#This Row],[Category]]) -> 0 | T110: =IF(_USDashboardTable5727[[#Totals],[Market Value (in USD)]]>0,_USDashboardTable5727[[#This Row],[Market Value (in USD)]]/_USDashboardTable5727[[#Totals],[Market Value (in USD)]],0) -> 0 | V110: ETF | W110: =COUNTIFS(_TrackerTable35[Country],V$105,_TrackerTable35[Category],_USDashboardTable571433[[#This Row],[Category]]) -> 0 | X110: =SUMIFS(_TrackerTable35[Market Value (in USD)],_TrackerTable35[Country],V$105,_TrackerTable35[Category],_USDashboardTable571433[[#This Row],[Category]]) -> 0 | Y110: =IF(_USDashboardTable571433[[#Totals],[Market Value (in USD)]]>0,_USDashboardTable571433[[#This Row],[Market Value (in USD)]]/_USDashboardTable571433[[#Totals],[Market Value (in USD)]],0) -> 0
B111: Growth | C111: =COUNTIFS(_TrackerTable35[Category],_USDashboardTable5626[[#This Row],[Category]]) -> 5 | D111: =SUMIFS(_TrackerTable35[Market Value (in USD)],_TrackerTable35[Category],_USDashboardTable5626[[#This Row],[Category]]) -> 30648.528 | E111: =IF(_USDashboardTable5626[[#Totals],[Market Value (in USD)]]>0,_USDashboardTable5626[[#This Row],[Market Value (in USD)]]/_USDashboardTable5626[[#Totals],[Market Value (in USD)]],0) -> 0.576955 | G111: Growth | H111: =COUNTIFS(_TrackerTable35[Country],G$105,_TrackerTable35[Category],_USDashboardTable24[[#This Row],[Category]]) -> 3 | I111: =SUMIFS(_TrackerTable35[Market Value (in USD)],_TrackerTable35[Country],G$105,_TrackerTable35[Category],_USDashboardTable24[[#This Row],[Category]]) -> 20501.16 | J111: =IF(_USDashboardTable24[[#Totals],[Market Value (in USD)]]>0,_USDashboardTable24[[#This Row],[Market Value (in USD)]]/_USDashboardTable24[[#Totals],[Market Value (in USD)]],0) -> 0.60172795 | L111: Growth | M111: =COUNTIFS(_TrackerTable35[Country],L$105,_TrackerTable35[Category],_USDashboardTable525[[#This Row],[Category]]) -> 2 | N111: =SUMIFS(_TrackerTable35[Market Value (in USD)],_TrackerTable35[Country],L$105,_TrackerTable35[Category],_USDashboardTable525[[#This Row],[Category]]) -> 10147.368 | O111: =IF(_USDashboardTable525[[#Totals],[Market Value (in USD)]]>0,_USDashboardTable525[[#This Row],[Market Value (in USD)]]/_USDashboardTable525[[#Totals],[Market Value (in USD)]],0) -> 0.63017158 | Q111: Growth | R111: =COUNTIFS(_TrackerTable35[Country],Q$105,_TrackerTable35[Category],_USDashboardTable5727[[#This Row],[Category]]) -> 0 | S111: =SUMIFS(_TrackerTable35[Market Value (in USD)],_TrackerTable35[Country],Q$105,_TrackerTable35[Category],_USDashboardTable5727[[#This Row],[Category]]) -> 0 | T111: =IF(_USDashboardTable5727[[#Totals],[Market Value (in USD)]]>0,_USDashboardTable5727[[#This Row],[Market Value (in USD)]]/_USDashboardTable5727[[#Totals],[Market Value (in USD)]],0) -> 0 | V111: Growth | W111: =COUNTIFS(_TrackerTable35[Country],V$105,_TrackerTable35[Category],_USDashboardTable571433[[#This Row],[Category]]) -> 0 | X111: =SUMIFS(_TrackerTable35[Market Value (in USD)],_TrackerTable35[Country],V$105,_TrackerTable35[Category],_USDashboardTable571433[[#This Row],[Category]]) -> 0 | Y111: =IF(_USDashboardTable571433[[#Totals],[Market Value (in USD)]]>0,_USDashboardTable571433[[#This Row],[Market Value (in USD)]]/_USDashboardTable571433[[#Totals],[Market Value (in USD)]],0) -> 0
B112: Other | C112: =COUNTIFS(_TrackerTable35[Category],_USDashboardTable5626[[#This Row],[Category]]) -> 0 | D112: =SUMIFS(_TrackerTable35[Market Value (in USD)],_TrackerTable35[Category],_USDashboardTable5626[[#This Row],[Category]]) -> 0 | E112: =IF(_USDashboardTable5626[[#Totals],[Market Value (in USD)]]>0,_USDashboardTable5626[[#This Row],[Market Value (in USD)]]/_USDashboardTable5626[[#Totals],[Market Value (in USD)]],0) -> 0 | G112: Other | H112: =COUNTIFS(_TrackerTable35[Country],G$105,_TrackerTable35[Category],_USDashboardTable24[[#This Row],[Category]]) -> 0 | I112: =SUMIFS(_TrackerTable35[Market Value (in USD)],_TrackerTable35[Country],G$105,_TrackerTable35[Category],_USDashboardTable24[[#This Row],[Category]]) -> 0 | J112: =IF(_USDashboardTable24[[#Totals],[Market Value (in USD)]]>0,_USDashboardTable24[[#This Row],[Market Value (in USD)]]/_USDashboardTable24[[#Totals],[Market Value (in USD)]],0) -> 0 | L112: Other | M112: =COUNTIFS(_TrackerTable35[Country],L$105,_TrackerTable35[Category],_USDashboardTable525[[#This Row],[Category]]) -> 0 | N112: =SUMIFS(_TrackerTable35[Market Value (in USD)],_TrackerTable35[Country],L$105,_TrackerTable35[Category],_USDashboardTable525[[#This Row],[Category]]) -> 0 | O112: =IF(_USDashboardTable525[[#Totals],[Market Value (in USD)]]>0,_USDashboardTable525[[#This Row],[Market Value (in USD)]]/_USDashboardTable525[[#Totals],[Market Value (in USD)]],0) -> 0 | Q112: Other | R112: =COUNTIFS(_TrackerTable35[Country],Q$105,_TrackerTable35[Category],_USDashboardTable5727[[#This Row],[Category]]) -> 0 | S112: =SUMIFS(_TrackerTable35[Market Value (in USD)],_TrackerTable35[Country],Q$105,_TrackerTable35[Category],_USDashboardTable5727[[#This Row],[Category]]) -> 0 | T112: =IF(_USDashboardTable5727[[#Totals],[Market Value (in USD)]]>0,_USDashboardTable5727[[#This Row],[Market Value (in USD)]]/_USDashboardTable5727[[#Totals],[Market Value (in USD)]],0) -> 0 | V112: Other | W112: =COUNTIFS(_TrackerTable35[Country],V$105,_TrackerTable35[Category],_USDashboardTable571433[[#This Row],[Category]]) -> 0 | X112: =SUMIFS(_TrackerTable35[Market Value (in USD)],_TrackerTable35[Country],V$105,_TrackerTable35[Category],_USDashboardTable571433[[#This Row],[Category]]) -> 0 | Y112: =IF(_USDashboardTable571433[[#Totals],[Market Value (in USD)]]>0,_USDashboardTable571433[[#This Row],[Market Value (in USD)]]/_USDashboardTable571433[[#Totals],[Market Value (in USD)]],0) -> 0
B113: Predictable | C113: =COUNTIFS(_TrackerTable35[Category],_USDashboardTable5626[[#This Row],[Category]]) -> 2 | D113: =SUMIFS(_TrackerTable35[Market Value (in USD)],_TrackerTable35[Category],_USDashboardTable5626[[#This Row],[Category]]) -> 13569.32 | E113: =IF(_USDashboardTable5626[[#Totals],[Market Value (in USD)]]>0,_USDashboardTable5626[[#This Row],[Market Value (in USD)]]/_USDashboardTable5626[[#Totals],[Market Value (in USD)]],0) -> 0.25544088 | G113: Predictable | H113: =COUNTIFS(_TrackerTable35[Country],G$105,_TrackerTable35[Category],_USDashboardTable24[[#This Row],[Category]]) -> 2 | I113: =SUMIFS(_TrackerTable35[Market Value (in USD)],_TrackerTable35[Country],G$105,_TrackerTable35[Category],_USDashboardTable24[[#This Row],[Category]]) -> 13569.32 | J113: =IF(_USDashboardTable24[[#Totals],[Market Value (in USD)]]>0,_USDashboardTable24[[#This Row],[Market Value (in USD)]]/_USDashboardTable24[[#Totals],[Market Value (in USD)]],0) -> 0.39827205 | L113: Predictable | M113: =COUNTIFS(_TrackerTable35[Country],L$105,_TrackerTable35[Category],_USDashboardTable525[[#This Row],[Category]]) -> 0 | N113: =SUMIFS(_TrackerTable35[Market Value (in USD)],_TrackerTable35[Country],L$105,_TrackerTable35[Category],_USDashboardTable525[[#This Row],[Category]]) -> 0 | O113: =IF(_USDashboardTable525[[#Totals],[Market Value (in USD)]]>0,_USDashboardTable525[[#This Row],[Market Value (in USD)]]/_USDashboardTable525[[#Totals],[Market Value (in USD)]],0) -> 0 | Q113: Predictable | R113: =COUNTIFS(_TrackerTable35[Country],Q$105,_TrackerTable35[Category],_USDashboardTable5727[[#This Row],[Category]]) -> 0 | S113: =SUMIFS(_TrackerTable35[Market Value (in USD)],_TrackerTable35[Country],Q$105,_TrackerTable35[Category],_USDashboardTable5727[[#This Row],[Category]]) -> 0 | T113: =IF(_USDashboardTable5727[[#Totals],[Market Value (in USD)]]>0,_USDashboardTable5727[[#This Row],[Market Value (in USD)]]/_USDashboardTable5727[[#Totals],[Market Value (in USD)]],0) -> 0 | V113: Predictable | W113: =COUNTIFS(_TrackerTable35[Country],V$105,_TrackerTable35[Category],_USDashboardTable571433[[#This Row],[Category]]) -> 0 | X113: =SUMIFS(_TrackerTable35[Market Value (in USD)],_TrackerTable35[Country],V$105,_TrackerTable35[Category],_USDashboardTable571433[[#This Row],[Category]]) -> 0 | Y113: =IF(_USDashboardTable571433[[#Totals],[Market Value (in USD)]]>0,_USDashboardTable571433[[#This Row],[Market Value (in USD)]]/_USDashboardTable571433[[#Totals],[Market Value (in USD)]],0) -> 0
B114: Speculative | C114: =COUNTIFS(_TrackerTable35[Category],_USDashboardTable5626[[#This Row],[Category]]) -> 0 | D114: =SUMIFS(_TrackerTable35[Market Value (in USD)],_TrackerTable35[Category],_USDashboardTable5626[[#This Row],[Category]]) -> 0 | E114: =IF(_USDashboardTable5626[[#Totals],[Market Value (in USD)]]>0,_USDashboardTable5626[[#This Row],[Market Value (in USD)]]/_USDashboardTable5626[[#Totals],[Market Value (in USD)]],0) -> 0 | G114: Speculative | H114: =COUNTIFS(_TrackerTable35[Country],G$105,_TrackerTable35[Category],_USDashboardTable24[[#This Row],[Category]]) -> 0 | I114: =SUMIFS(_TrackerTable35[Market Value (in USD)],_TrackerTable35[Country],G$105,_TrackerTable35[Category],_USDashboardTable24[[#This Row],[Category]]) -> 0 | J114: =IF(_USDashboardTable24[[#Totals],[Market Value (in USD)]]>0,_USDashboardTable24[[#This Row],[Market Value (in USD)]]/_USDashboardTable24[[#Totals],[Market Value (in USD)]],0) -> 0 | L114: Speculative | M114: =COUNTIFS(_TrackerTable35[Country],L$105,_TrackerTable35[Category],_USDashboardTable525[[#This Row],[Category]]) -> 0 | N114: =SUMIFS(_TrackerTable35[Market Value (in USD)],_TrackerTable35[Country],L$105,_TrackerTable35[Category],_USDashboardTable525[[#This Row],[Category]]) -> 0 | O114: =IF(_USDashboardTable525[[#Totals],[Market Value (in USD)]]>0,_USDashboardTable525[[#This Row],[Market Value (in USD)]]/_USDashboardTable525[[#Totals],[Market Value (in USD)]],0) -> 0 | Q114: Speculative | R114: =COUNTIFS(_TrackerTable35[Country],Q$105,_TrackerTable35[Category],_USDashboardTable5727[[#This Row],[Category]]) -> 0 | S114: =SUMIFS(_TrackerTable35[Market Value (in USD)],_TrackerTable35[Country],Q$105,_TrackerTable35[Category],_USDashboardTable5727[[#This Row],[Category]]) -> 0 | T114: =IF(_USDashboardTable5727[[#Totals],[Market Value (in USD)]]>0,_USDashboardTable5727[[#This Row],[Market Value (in USD)]]/_USDashboardTable5727[[#Totals],[Market Value (in USD)]],0) -> 0 | V114: Speculative | W114: =COUNTIFS(_TrackerTable35[Country],V$105,_TrackerTable35[Category],_USDashboardTable571433[[#This Row],[Category]]) -> 0 | X114: =SUMIFS(_TrackerTable35[Market Value (in USD)],_TrackerTable35[Country],V$105,_TrackerTable35[Category],_USDashboardTable571433[[#This Row],[Category]]) -> 0 | Y114: =IF(_USDashboardTable571433[[#Totals],[Market Value (in USD)]]>0,_USDashboardTable571433[[#This Row],[Market Value (in USD)]]/_USDashboardTable571433[[#Totals],[Market Value (in USD)]],0) -> 0
B115: Turnaround | C115: =COUNTIFS(_TrackerTable35[Category],_USDashboardTable5626[[#This Row],[Category]]) -> 0 | D115: =SUMIFS(_TrackerTable35[Market Value (in USD)],_TrackerTable35[Category],_USDashboardTable5626[[#This Row],[Category]]) -> 0 | E115: =IF(_USDashboardTable5626[[#Totals],[Market Value (in USD)]]>0,_USDashboardTable5626[[#This Row],[Market Value (in USD)]]/_USDashboardTable5626[[#Totals],[Market Value (in USD)]],0) -> 0 | G115: Turnaround | H115: =COUNTIFS(_TrackerTable35[Country],G$105,_TrackerTable35[Category],_USDashboardTable24[[#This Row],[Category]]) -> 0 | I115: =SUMIFS(_TrackerTable35[Market Value (in USD)],_TrackerTable35[Country],G$105,_TrackerTable35[Category],_USDashboardTable24[[#This Row],[Category]]) -> 0 | J115: =IF(_USDashboardTable24[[#Totals],[Market Value (in USD)]]>0,_USDashboardTable24[[#This Row],[Market Value (in USD)]]/_USDashboardTable24[[#Totals],[Market Value (in USD)]],0) -> 0 | L115: Turnaround | M115: =COUNTIFS(_TrackerTable35[Country],L$105,_TrackerTable35[Category],_USDashboardTable525[[#This Row],[Category]]) -> 0 | N115: =SUMIFS(_TrackerTable35[Market Value (in USD)],_TrackerTable35[Country],L$105,_TrackerTable35[Category],_USDashboardTable525[[#This Row],[Category]]) -> 0 | O115: =IF(_USDashboardTable525[[#Totals],[Market Value (in USD)]]>0,_USDashboardTable525[[#This Row],[Market Value (in USD)]]/_USDashboardTable525[[#Totals],[Market Value (in USD)]],0) -> 0 | Q115: Turnaround | R115: =COUNTIFS(_TrackerTable35[Country],Q$105,_TrackerTable35[Category],_USDashboardTable5727[[#This Row],[Category]]) -> 0 | S115: =SUMIFS(_TrackerTable35[Market Value (in USD)],_TrackerTable35[Country],Q$105,_TrackerTable35[Category],_USDashboardTable5727[[#This Row],[Category]]) -> 0 | T115: =IF(_USDashboardTable5727[[#Totals],[Market Value (in USD)]]>0,_USDashboardTable5727[[#This Row],[Market Value (in USD)]]/_USDashboardTable5727[[#Totals],[Market Value (in USD)]],0) -> 0 | V115: Turnaround | W115: =COUNTIFS(_TrackerTable35[Country],V$105,_TrackerTable35[Category],_USDashboardTable571433[[#This Row],[Category]]) -> 0 | X115: =SUMIFS(_TrackerTable35[Market Value (in USD)],_TrackerTable35[Country],V$105,_TrackerTable35[Category],_USDashboardTable571433[[#This Row],[Category]]) -> 0 | Y115: =IF(_USDashboardTable571433[[#Totals],[Market Value (in USD)]]>0,_USDashboardTable571433[[#This Row],[Market Value (in USD)]]/_USDashboardTable571433[[#Totals],[Market Value (in USD)]],0) -> 0
B116: TOTAL | C116: =SUBTOTAL(109,_USDashboardTable5626[Count]) -> 9 | D116: =SUBTOTAL(109,_USDashboardTable5626[Market Value (in USD)]) -> 53121.177 | E116: =SUBTOTAL(109,_USDashboardTable5626[Percentage by Market Value]) -> 1 | G116: TOTAL | H116: =SUBTOTAL(109,_USDashboardTable24[Count]) -> 5 | I116: =SUBTOTAL(109,_USDashboardTable24[Market Value (in USD)]) -> 34070.48 | J116: =SUBTOTAL(109,_USDashboardTable24[Percentage by Market Value]) -> 1 | L116: TOTAL | M116: =SUBTOTAL(109,_USDashboardTable525[Count]) -> 3 | N116: =SUBTOTAL(109,_USDashboardTable525[Market Value (in USD)]) -> 16102.548 | O116: =SUBTOTAL(109,_USDashboardTable525[Percentage by Market Value]) -> 1 | Q116: TOTAL | R116: =SUBTOTAL(109,_USDashboardTable5727[Count]) -> 1 | S116: =SUBTOTAL(109,_USDashboardTable5727[Market Value (in USD)]) -> 2948.1481 | T116: =SUBTOTAL(109,_USDashboardTable5727[Percentage by Market Value]) -> 1 | V116: TOTAL | W116: =SUBTOTAL(109,_USDashboardTable571433[Count]) -> 0 | X116: =SUBTOTAL(109,_USDashboardTable571433[Market Value (in USD)]) -> 0 | Y116: =SUBTOTAL(109,_USDashboardTable571433[Percentage by Market Value]) -> 0
B168: Breakdown by Sector (Market Value)
B169: TOTAL | G169: US | L169: China/HK | Q169: Singapore | V169: Australia
B170: Sector | C170: Count | D170: Market Value (in USD) | E170: Percentage by Market Value | G170: Sector | H170: Count | I170: Market Value (in USD) | J170: Percentage by Market Value | L170: Sector | M170: Count | N170: Market Value (in USD) | O170: Percentage by Market Value | Q170: Sector | R170: Count | S170: Market Value (in USD) | T170: Percentage by Market Value | V170: Sector | W170: Count | X170: Market Value (in USD) | Y170: Percentage by Market Value
B171: Communication Services | C171: =COUNTIFS(_TrackerTable35[Sector],_USDashboardTable56265[[#This Row],[Sector]]) -> 2 | D171: =SUMIFS(_TrackerTable35[Market Value (in USD)],_TrackerTable35[Sector],_USDashboardTable56265[[#This Row],[Sector]]) -> 16256.16 | E171: =IF(_USDashboardTable56265[[#Totals],[Market Value (in USD)]]>0,_USDashboardTable56265[[#This Row],[Market Value (in USD)]]/_USDashboardTable56265[[#Totals],[Market Value (in USD)]],0) -> 0.30602033 | G171: Communication Services | H171: =COUNTIFS(_TrackerTable35[Country],G$169,_TrackerTable35[Sector],_USDashboardTable243[[#This Row],[Sector]]) -> 1 | I171: =SUMIFS(_TrackerTable35[Market Value (in USD)],_TrackerTable35[Country],G$169,_TrackerTable35[Sector],_USDashboardTable243[[#This Row],[Sector]]) -> 11314.44 | J171: =IF(_USDashboardTable243[[#Totals],[Market Value (in USD)]]>0,_USDashboardTable243[[#This Row],[Market Value (in USD)]]/_USDashboardTable243[[#Totals],[Market Value (in USD)]],0) -> 0.33208925 | L171: Communication Services | M171: =COUNTIFS(_TrackerTable35[Country],L$169,_TrackerTable35[Sector],_USDashboardTable5254[[#This Row],[Sector]]) -> 1 | N171: =SUMIFS(_TrackerTable35[Market Value (in USD)],_TrackerTable35[Country],L$169,_TrackerTable35[Sector],_USDashboardTable5254[[#This Row],[Sector]]) -> 4941.7202 | O171: =IF(_USDashboardTable5254[[#Totals],[Market Value (in USD)]]>0,_USDashboardTable5254[[#This Row],[Market Value (in USD)]]/_USDashboardTable5254[[#Totals],[Market Value (in USD)]],0) -> 0.30689056 | Q171: Communication Services | R171: =COUNTIFS(_TrackerTable35[Country],Q$169,_TrackerTable35[Sector],_USDashboardTable57276[[#This Row],[Sector]]) -> 0 | S171: =SUMIFS(_TrackerTable35[Market Value (in USD)],_TrackerTable35[Country],Q$169,_TrackerTable35[Sector],_USDashboardTable57276[[#This Row],[Sector]]) -> 0 | T171: =IF(_USDashboardTable57276[[#Totals],[Market Value (in USD)]]>0,_USDashboardTable57276[[#This Row],[Market Value (in USD)]]/_USDashboardTable57276[[#Totals],[Market Value (in USD)]],0) -> 0 | V171: Communication Services | W171: =COUNTIFS(_TrackerTable35[Country],V$169,_TrackerTable35[Sector],_USDashboardTable5714337[[#This Row],[Sector]]) -> 0 | X171: =SUMIFS(_TrackerTable35[Market Value (in USD)],_TrackerTable35[Country],V$169,_TrackerTable35[Sector],_USDashboardTable5714337[[#This Row],[Sector]]) -> 0 | Y171: =IF(_USDashboardTable5714337[[#Totals],[Market Value (in USD)]]>0,_USDashboardTable5714337[[#This Row],[Market Value (in USD)]]/_USDashboardTable5714337[[#Totals],[Market Value (in USD)]],0) -> 0
B172: Consumer Discretionary | C172: =COUNTIFS(_TrackerTable35[Sector],_USDashboardTable56265[[#This Row],[Sector]]) -> 1 | D172: =SUMIFS(_TrackerTable35[Market Value (in USD)],_TrackerTable35[Sector],_USDashboardTable56265[[#This Row],[Sector]]) -> 5205.6483 | E172: =IF(_USDashboardTable56265[[#Totals],[Market Value (in USD)]]>0,_USDashboardTable56265[[#This Row],[Market Value (in USD)]]/_USDashboardTable56265[[#Totals],[Market Value (in USD)]],0) -> 0.097995726 | G172: Consumer Discretionary | H172: =COUNTIFS(_TrackerTable35[Country],G$169,_TrackerTable35[Sector],_USDashboardTable243[[#This Row],[Sector]]) -> 0 | I172: =SUMIFS(_TrackerTable35[Market Value (in USD)],_TrackerTable35[Country],G$169,_TrackerTable35[Sector],_USDashboardTable243[[#This Row],[Sector]]) -> 0 | J172: =IF(_USDashboardTable243[[#Totals],[Market Value (in USD)]]>0,_USDashboardTable243[[#This Row],[Market Value (in USD)]]/_USDashboardTable243[[#Totals],[Market Value (in USD)]],0) -> 0 | L172: Consumer Discretionary | M172: =COUNTIFS(_TrackerTable35[Country],L$169,_TrackerTable35[Sector],_USDashboardTable5254[[#This Row],[Sector]]) -> 1 | N172: =SUMIFS(_TrackerTable35[Market Value (in USD)],_TrackerTable35[Country],L$169,_TrackerTable35[Sector],_USDashboardTable5254[[#This Row],[Sector]]) -> 5205.6483 | O172: =IF(_USDashboardTable5254[[#Totals],[Market Value (in USD)]]>0,_USDashboardTable5254[[#This Row],[Market Value (in USD)]]/_USDashboardTable5254[[#Totals],[Market Value (in USD)]],0) -> 0.32328102 | Q172: Consumer Discretionary | R172: =COUNTIFS(_TrackerTable35[Country],Q$169,_TrackerTable35[Sector],_USDashboardTable57276[[#This Row],[Sector]]) -> 0 | S172: =SUMIFS(_TrackerTable35[Market Value (in USD)],_TrackerTable35[Country],Q$169,_TrackerTable35[Sector],_USDashboardTable57276[[#This Row],[Sector]]) -> 0 | T172: =IF(_USDashboardTable57276[[#Totals],[Market Value (in USD)]]>0,_USDashboardTable57276[[#This Row],[Market Value (in USD)]]/_USDashboardTable57276[[#Totals],[Market Value (in USD)]],0) -> 0 | V172: Consumer Discretionary | W172: =COUNTIFS(_TrackerTable35[Country],V$169,_TrackerTable35[Sector],_USDashboardTable5714337[[#This Row],[Sector]]) -> 0 | X172: =SUMIFS(_TrackerTable35[Market Value (in USD)],_TrackerTable35[Country],V$169,_TrackerTable35[Sector],_USDashboardTable5714337[[#This Row],[Sector]]) -> 0 | Y172: =IF(_USDashboardTable5714337[[#Totals],[Market Value (in USD)]]>0,_USDashboardTable5714337[[#This Row],[Market Value (in USD)]]/_USDashboardTable5714337[[#Totals],[Market Value (in USD)]],0) -> 0
B173: Consumer Staples | C173: =COUNTIFS(_TrackerTable35[Sector],_USDashboardTable56265[[#This Row],[Sector]]) -> 1 | D173: =SUMIFS(_TrackerTable35[Market Value (in USD)],_TrackerTable35[Sector],_USDashboardTable56265[[#This Row],[Sector]]) -> 6783.92 | E173: =IF(_USDashboardTable56265[[#Totals],[Market Value (in USD)]]>0,_USDashboardTable56265[[#This Row],[Market Value (in USD)]]/_USDashboardTable56265[[#Totals],[Market Value (in USD)]],0) -> 0.12770651 | G173: Consumer Staples | H173: =COUNTIFS(_TrackerTable35[Country],G$169,_TrackerTable35[Sector],_USDashboardTable243[[#This Row],[Sector]]) -> 1 | I173: =SUMIFS(_TrackerTable35[Market Value (in USD)],_TrackerTable35[Country],G$169,_TrackerTable35[Sector],_USDashboardTable243[[#This Row],[Sector]]) -> 6783.92 | J173: =IF(_USDashboardTable243[[#Totals],[Market Value (in USD)]]>0,_USDashboardTable243[[#This Row],[Market Value (in USD)]]/_USDashboardTable243[[#Totals],[Market Value (in USD)]],0) -> 0.19911431 | L173: Consumer Staples | M173: =COUNTIFS(_TrackerTable35[Country],L$169,_TrackerTable35[Sector],_USDashboardTable5254[[#This Row],[Sector]]) -> 0 | N173: =SUMIFS(_TrackerTable35[Market Value (in USD)],_TrackerTable35[Country],L$169,_TrackerTable35[Sector],_USDashboardTable5254[[#This Row],[Sector]]) -> 0 | O173: =IF(_USDashboardTable5254[[#Totals],[Market Value (in USD)]]>0,_USDashboardTable5254[[#This Row],[Market Value (in USD)]]/_USDashboardTable5254[[#Totals],[Market Value (in USD)]],0) -> 0 | Q173: Consumer Staples | R173: =COUNTIFS(_TrackerTable35[Country],Q$169,_TrackerTable35[Sector],_USDashboardTable57276[[#This Row],[Sector]]) -> 0 | S173: =SUMIFS(_TrackerTable35[Market Value (in USD)],_TrackerTable35[Country],Q$169,_TrackerTable35[Sector],_USDashboardTable57276[[#This Row],[Sector]]) -> 0 | T173: =IF(_USDashboardTable57276[[#Totals],[Market Value (in USD)]]>0,_USDashboardTable57276[[#This Row],[Market Value (in USD)]]/_USDashboardTable57276[[#Totals],[Market Value (in USD)]],0) -> 0 | V173: Consumer Staples | W173: =COUNTIFS(_TrackerTable35[Country],V$169,_TrackerTable35[Sector],_USDashboardTable5714337[[#This Row],[Sector]]) -> 0 | X173: =SUMIFS(_TrackerTable35[Market Value (in USD)],_TrackerTable35[Country],V$169,_TrackerTable35[Sector],_USDashboardTable5714337[[#This Row],[Sector]]) -> 0 | Y173: =IF(_USDashboardTable5714337[[#Totals],[Market Value (in USD)]]>0,_USDashboardTable5714337[[#This Row],[Market Value (in USD)]]/_USDashboardTable5714337[[#Totals],[Market Value (in USD)]],0) -> 0
B174: Diversified | C174: =COUNTIFS(_TrackerTable35[Sector],_USDashboardTable56265[[#This Row],[Sector]]) -> 1 | D174: =SUMIFS(_TrackerTable35[Market Value (in USD)],_TrackerTable35[Sector],_USDashboardTable56265[[#This Row],[Sector]]) -> 5955.18 | E174: =IF(_USDashboardTable56265[[#Totals],[Market Value (in USD)]]>0,_USDashboardTable56265[[#This Row],[Market Value (in USD)]]/_USDashboardTable56265[[#Totals],[Market Value (in USD)]],0) -> 0.11210557 | G174: Diversified | H174: =COUNTIFS(_TrackerTable35[Country],G$169,_TrackerTable35[Sector],_USDashboardTable243[[#This Row],[Sector]]) -> 0 | I174: =SUMIFS(_TrackerTable35[Market Value (in USD)],_TrackerTable35[Country],G$169,_TrackerTable35[Sector],_USDashboardTable243[[#This Row],[Sector]]) -> 0 | J174: =IF(_USDashboardTable243[[#Totals],[Market Value (in USD)]]>0,_USDashboardTable243[[#This Row],[Market Value (in USD)]]/_USDashboardTable243[[#Totals],[Market Value (in USD)]],0) -> 0 | L174: Diversified | M174: =COUNTIFS(_TrackerTable35[Country],L$169,_TrackerTable35[Sector],_USDashboardTable5254[[#This Row],[Sector]]) -> 1 | N174: =SUMIFS(_TrackerTable35[Market Value (in USD)],_TrackerTable35[Country],L$169,_TrackerTable35[Sector],_USDashboardTable5254[[#This Row],[Sector]]) -> 5955.18 | O174: =IF(_USDashboardTable5254[[#Totals],[Market Value (in USD)]]>0,_USDashboardTable5254[[#This Row],[Market Value (in USD)]]/_USDashboardTable5254[[#Totals],[Market Value (in USD)]],0) -> 0.36982842 | Q174: Diversified | R174: =COUNTIFS(_TrackerTable35[Country],Q$169,_TrackerTable35[Sector],_USDashboardTable57276[[#This Row],[Sector]]) -> 0 | S174: =SUMIFS(_TrackerTable35[Market Value (in USD)],_TrackerTable35[Country],Q$169,_TrackerTable35[Sector],_USDashboardTable57276[[#This Row],[Sector]]) -> 0 | T174: =IF(_USDashboardTable57276[[#Totals],[Market Value (in USD)]]>0,_USDashboardTable57276[[#This Row],[Market Value (in USD)]]/_USDashboardTable57276[[#Totals],[Market Value (in USD)]],0) -> 0 | V174: Diversified | W174: =COUNTIFS(_TrackerTable35[Country],V$169,_TrackerTable35[Sector],_USDashboardTable5714337[[#This Row],[Sector]]) -> 0 | X174: =SUMIFS(_TrackerTable35[Market Value (in USD)],_TrackerTable35[Country],V$169,_TrackerTable35[Sector],_USDashboardTable5714337[[#This Row],[Sector]]) -> 0 | Y174: =IF(_USDashboardTable5714337[[#Totals],[Market Value (in USD)]]>0,_USDashboardTable5714337[[#This Row],[Market Value (in USD)]]/_USDashboardTable5714337[[#Totals],[Market Value (in USD)]],0) -> 0
